<?xml version="1.0"?>
<robot xmlns:xacro="http://ros.org/wiki/xacro">
    <!--tether model-->
    <xacro:macro name="tether">
        <!--tether fragment param-->
        {%- set lump_mass = 0.05 -%}
        {%- set lump_radius = 0.03 -%}
        {%- set lump_inertia = 3*lump_mass*lump_radius**2 -%}
        {%- set element_length = 10.0 -%}
        <!--joint dynamics-->
        {%- set damping = 1 -%}
        {%- set friction = 1 -%}
        <!--link number-->
        {%- set tether_fragments = 2 -%}
        {%- set tether_number = 4 -%}

        {%- macro tether_fragment(dirc, n) -%}
        <link name="tether_{{dirc}}/fragment_{{n}}_1">
            <visual>
                <origin rpy="0 0 0" xyz="0 0 0"/>
                <geometry>
                    <sphere radius="{{lump_radius}}"/>
                </geometry>
            </visual>
            <inertial>
                <mass value="{{lump_mass}}"/>
                <inertia ixx="{{lump_inertia}}" iyy="{{lump_inertia}}" izz="{{lump_inertia}}" ixy="0.0" ixz="0.0" iyz="0.0"/>
            </inertial>
        </link>
        <gazebo reference="tether_{{dirc}}/fragment_{{n}}_1">
            <material>Gazebo/Red</material>
        </gazebo>

        <link name="tether_{{dirc}}/fragment_{{n}}_2">
            <visual>
                <origin rpy="0 0 0" xyz="0 0 0"/>
                <geometry>
                    <sphere radius="{{lump_radius}}"/>
                </geometry>
            </visual>
            <inertial>
                <mass value="{{lump_mass}}"/>
                <inertia ixx="{{lump_inertia}}" iyy="{{lump_inertia}}" izz="{{lump_inertia}}" ixy="0.0" ixz="0.0" iyz="0.0"/>
            </inertial>
        </link>
        <gazebo reference="tether_{{dirc}}/fragment_{{n}}_2">
            <material>Gazebo/Red</material>
        </gazebo>

        <link name="tether_{{dirc}}/fragment_{{n}}_3">
            <visual>
                <origin rpy="0 0 0" xyz="0 0 0"/>
                <geometry>
                    <sphere radius="{{lump_radius}}"/>
                </geometry>
            </visual>
            <inertial>
                <mass value="{{lump_mass}}"/>
                <inertia ixx="{{lump_inertia}}" iyy="{{lump_inertia}}" izz="{{lump_inertia}}" ixy="0.0" ixz="0.0" iyz="0.0"/>
            </inertial>
        </link>
        <gazebo reference="tether_{{dirc}}/fragment_{{n}}_3">
            <material>Gazebo/Red</material>
        </gazebo>
        {%- endmacro -%}

        <!--tether_cylinder_joint-->
        {%- macro tether_joint(dirc, n) -%}
        <!--tether fragment joint-->
        <joint name="tether_{{dirc}}/joint_roll_{{n}}" type="continuous">
            <origin rpy="0 0 0" xyz="0 0 {{element_length}}"/>
            <parent link="tether_{{dirc}}/fragment_{{n-1}}_3"/>
            <child link="tether_{{dirc}}/fragment_{{n}}_1"/>
            <axis xyz="1 0 0" />
            <dynamics damping="{{damping}}" friction="{{friction}}"/>
        </joint>

        <joint name="tether_{{dirc}}/joint_pitch_{{n}}" type="continuous">
            <origin rpy="0 0 0" xyz="0 0 0"/>
            <parent link="tether_{{dirc}}/fragment_{{n}}_1"/>
            <child link="tether_{{dirc}}/fragment_{{n}}_2"/>
            <axis xyz="0 1 0" />
            <dynamics damping="{{damping}}" friction="{{friction}}"/>
        </joint>

        <joint name="tether_{{dirc}}/joint_yaw_{{n}}" type="continuous">
            <origin rpy="0 0 0" xyz="0 0 0"/>
            <parent link="tether_{{dirc}}/fragment_{{n}}_2"/>
            <child link="tether_{{dirc}}/fragment_{{n}}_3"/>
            <axis xyz="0 0 1" />
            <dynamics damping="{{damping}}" friction="{{friction}}"/>
        </joint>
        {%- endmacro -%}

        {%- macro uav_joint(dirc) -%}
        <link name="tether_{{dirc}}/rod">
            <visual>
                <origin rpy="0 0 0" xyz="0 0 0.1"/>
                <geometry>
                    <cylinder length="0.2" radius="0.01"/>
                </geometry>
            </visual>
            <inertial>
                <mass value="0.01"/>
                <inertia ixx="0.01" iyy="0.01" izz="0.01" ixy="0.0" ixz="0.0" iyz="0.0"/>
            </inertial>
            <collision>
                <geometry>
                    <cylinder length="0.2" radius="0.01"/>
                </geometry>
            </collision>
        </link>
        <gazebo reference="tether_{{dirc}}/rod">
            <material>Gazebo/Orange</material>
        </gazebo>
        <!--uav => tether joint-->
        <joint name="tether_{{dirc}}/rod_joint" type="fixed">
            <parent link="${namespace}/base_link"/>
            <child link="tether_{{dirc}}/rod"/>
            {% if dirc == 0 %}
                <origin rpy="0 ${pi/2} 0" xyz="0 0 0"/>
            {% elif dirc == 1 %}
                <origin rpy="${pi/2} 0 0" xyz="0 0 0"/>
            {% elif dirc == 2 %}
                <origin rpy="0 ${-pi/2} 0" xyz="0 0 0"/>
            {% elif dirc == 3 %}
                <origin rpy="${-pi/2} 0 0" xyz="0 0 0"/>
            {% endif %}
        </joint>

        <joint name="tether_{{dirc}}/uav_roll_joint" type="continuous">
            <origin rpy="0 0 0" xyz="0 0 0.2"/>
            <parent link="tether_{{dirc}}/rod"/>
            <child link="tether_{{dirc}}/fragment_0_1"/>
            <axis xyz="1 0 0" />
            <dynamics damping="{{damping}}" friction="{{friction}}"/>
        </joint>

        <joint name="tether_{{dirc}}/uav_pitch_joint" type="continuous">
            <origin rpy="0 0 0" xyz="0 0 0"/>
            <parent link="tether_{{dirc}}/fragment_0_1"/>
            <child link="tether_{{dirc}}/fragment_0_2"/>
            <axis xyz="0 1 0" />
            <dynamics damping="{{damping}}" friction="{{friction}}"/>
        </joint>

        <joint name="tether_{{dirc}}/joint_yaw_joint" type="continuous">
            <origin rpy="0 0 0" xyz="0 0 0"/>
            <parent link="tether_{{dirc}}/fragment_0_2"/>
            <child link="tether_{{dirc}}/fragment_0_3"/>
            <axis xyz="0 0 1" />
            <dynamics damping="{{damping}}" friction="{{friction}}"/>
        </joint>
        {%- endmacro -%}

        {%- macro ugv_joint(dirc) -%}
        <!--tether end joint-->
        <joint name="tether_{{dirc}}/ugv_joint_1" type="continuous">
            {% if dirc == 0 %}
                <origin rpy="0 ${-pi/2} 0" xyz="0 0 {{element_length}}"/>
                <axis xyz="0 1 0" />
            {% elif dirc == 1 %}
                <origin rpy="${-pi/2} 0 0" xyz="0 0 {{element_length}}"/>
                <axis xyz="1 0 0" />
            {% elif dirc == 2 %}
                <origin rpy="0 ${pi/2} 0" xyz="0 0 {{element_length}}"/>
                <axis xyz="0 1 0" />
            {% elif dirc == 3 %}
                <origin rpy="${pi/2} 0 0" xyz="0 0 {{element_length}}"/>
                <axis xyz="1 0 0" />
            {% endif %}
            <parent link="tether_{{dirc}}/fragment_{{tether_fragments-1}}_3"/>
            <child link="mp_500_{{dirc}}/tether_end"/>
            <dynamics damping="{{damping}}" friction="{{friction}}"/>
        </joint>
        {%- endmacro -%}

        <!-- main-->
        {% for dirc in range(0,tether_number) %}
            {% for n in range(0,tether_fragments) -%}
                {{tether_fragment(dirc, n)}}
                {% if n != 0 %}
                    {{tether_joint(dirc, n)}}
                {% endif %}
            {% endfor -%}
            {{uav_joint(dirc)}}
            {{ugv_joint(dirc)}}
        {% endfor -%}

    </xacro:macro>
</robot>
