<?xml version="1.0"?>
<robot xmlns:xacro="http://ros.org/wiki/xacro">
    <!--tether model-->
    <xacro:macro name="tether">
        <!--tether fragment param--><!--joint dynamics--><!--link number--><!--tether_cylinder_joint--><!-- main-->
        
            <link name="tether_0/fragment_0_1">
            <visual>
                <origin rpy="0 0 0" xyz="0 0 0"/>
                <geometry>
                    <sphere radius="0.03"/>
                </geometry>
            </visual>
            <inertial>
                <mass value="0.05"/>
                <inertia ixx="0.000135" iyy="0.000135" izz="0.000135" ixy="0.0" ixz="0.0" iyz="0.0"/>
            </inertial>
        </link>
        <gazebo reference="tether_0/fragment_0_1">
            <material>Gazebo/Red</material>
        </gazebo>

        <link name="tether_0/fragment_0_2">
            <visual>
                <origin rpy="0 0 0" xyz="0 0 0"/>
                <geometry>
                    <sphere radius="0.03"/>
                </geometry>
            </visual>
            <inertial>
                <mass value="0.05"/>
                <inertia ixx="0.000135" iyy="0.000135" izz="0.000135" ixy="0.0" ixz="0.0" iyz="0.0"/>
            </inertial>
        </link>
        <gazebo reference="tether_0/fragment_0_2">
            <material>Gazebo/Red</material>
        </gazebo>

        <link name="tether_0/fragment_0_3">
            <visual>
                <origin rpy="0 0 0" xyz="0 0 0"/>
                <geometry>
                    <sphere radius="0.03"/>
                </geometry>
            </visual>
            <inertial>
                <mass value="0.05"/>
                <inertia ixx="0.000135" iyy="0.000135" izz="0.000135" ixy="0.0" ixz="0.0" iyz="0.0"/>
            </inertial>
        </link>
        <gazebo reference="tether_0/fragment_0_3">
            <material>Gazebo/Red</material>
        </gazebo>
                
            <link name="tether_0/fragment_1_1">
            <visual>
                <origin rpy="0 0 0" xyz="0 0 0"/>
                <geometry>
                    <sphere radius="0.03"/>
                </geometry>
            </visual>
            <inertial>
                <mass value="0.05"/>
                <inertia ixx="0.000135" iyy="0.000135" izz="0.000135" ixy="0.0" ixz="0.0" iyz="0.0"/>
            </inertial>
        </link>
        <gazebo reference="tether_0/fragment_1_1">
            <material>Gazebo/Red</material>
        </gazebo>

        <link name="tether_0/fragment_1_2">
            <visual>
                <origin rpy="0 0 0" xyz="0 0 0"/>
                <geometry>
                    <sphere radius="0.03"/>
                </geometry>
            </visual>
            <inertial>
                <mass value="0.05"/>
                <inertia ixx="0.000135" iyy="0.000135" izz="0.000135" ixy="0.0" ixz="0.0" iyz="0.0"/>
            </inertial>
        </link>
        <gazebo reference="tether_0/fragment_1_2">
            <material>Gazebo/Red</material>
        </gazebo>

        <link name="tether_0/fragment_1_3">
            <visual>
                <origin rpy="0 0 0" xyz="0 0 0"/>
                <geometry>
                    <sphere radius="0.03"/>
                </geometry>
            </visual>
            <inertial>
                <mass value="0.05"/>
                <inertia ixx="0.000135" iyy="0.000135" izz="0.000135" ixy="0.0" ixz="0.0" iyz="0.0"/>
            </inertial>
        </link>
        <gazebo reference="tether_0/fragment_1_3">
            <material>Gazebo/Red</material>
        </gazebo>
                
                    <!--tether fragment joint-->
        <joint name="tether_0/joint_roll_1" type="continuous">
            <origin rpy="0 0 0" xyz="0 0 10.0"/>
            <parent link="tether_0/fragment_0_3"/>
            <child link="tether_0/fragment_1_1"/>
            <axis xyz="1 0 0" />
            <dynamics damping="1" friction="1"/>
        </joint>

        <joint name="tether_0/joint_pitch_1" type="continuous">
            <origin rpy="0 0 0" xyz="0 0 0"/>
            <parent link="tether_0/fragment_1_1"/>
            <child link="tether_0/fragment_1_2"/>
            <axis xyz="0 1 0" />
            <dynamics damping="1" friction="1"/>
        </joint>

        <joint name="tether_0/joint_yaw_1" type="continuous">
            <origin rpy="0 0 0" xyz="0 0 0"/>
            <parent link="tether_0/fragment_1_2"/>
            <child link="tether_0/fragment_1_3"/>
            <axis xyz="0 0 1" />
            <dynamics damping="1" friction="1"/>
        </joint>
                
            <link name="tether_0/rod">
            <visual>
                <origin rpy="0 0 0" xyz="0 0 0.1"/>
                <geometry>
                    <cylinder length="0.2" radius="0.01"/>
                </geometry>
            </visual>
            <inertial>
                <mass value="0.01"/>
                <inertia ixx="0.01" iyy="0.01" izz="0.01" ixy="0.0" ixz="0.0" iyz="0.0"/>
            </inertial>
            <collision>
                <geometry>
                    <cylinder length="0.2" radius="0.01"/>
                </geometry>
            </collision>
        </link>
        <gazebo reference="tether_0/rod">
            <material>Gazebo/Orange</material>
        </gazebo>
        <!--uav => tether joint-->
        <joint name="tether_0/rod_joint" type="fixed">
            <parent link="${namespace}/base_link"/>
            <child link="tether_0/rod"/>
            
                <origin rpy="0 ${pi/2} 0" xyz="0 0 0"/>
            
        </joint>

        <joint name="tether_0/uav_roll_joint" type="continuous">
            <origin rpy="0 0 0" xyz="0 0 0.2"/>
            <parent link="tether_0/rod"/>
            <child link="tether_0/fragment_0_1"/>
            <axis xyz="1 0 0" />
            <dynamics damping="1" friction="1"/>
        </joint>

        <joint name="tether_0/uav_pitch_joint" type="continuous">
            <origin rpy="0 0 0" xyz="0 0 0"/>
            <parent link="tether_0/fragment_0_1"/>
            <child link="tether_0/fragment_0_2"/>
            <axis xyz="0 1 0" />
            <dynamics damping="1" friction="1"/>
        </joint>

        <joint name="tether_0/joint_yaw_joint" type="continuous">
            <origin rpy="0 0 0" xyz="0 0 0"/>
            <parent link="tether_0/fragment_0_2"/>
            <child link="tether_0/fragment_0_3"/>
            <axis xyz="0 0 1" />
            <dynamics damping="1" friction="1"/>
        </joint>
            <!--tether end joint-->
        <joint name="tether_0/ugv_joint_1" type="continuous">
            
                <origin rpy="0 ${-pi/2} 0" xyz="0 0 10.0"/>
                <axis xyz="0 1 0" />
            
            <parent link="tether_0/fragment_1_3"/>
            <child link="mp_500_0/tether_end"/>
            <dynamics damping="1" friction="1"/>
        </joint>
        
            <link name="tether_1/fragment_0_1">
            <visual>
                <origin rpy="0 0 0" xyz="0 0 0"/>
                <geometry>
                    <sphere radius="0.03"/>
                </geometry>
            </visual>
            <inertial>
                <mass value="0.05"/>
                <inertia ixx="0.000135" iyy="0.000135" izz="0.000135" ixy="0.0" ixz="0.0" iyz="0.0"/>
            </inertial>
        </link>
        <gazebo reference="tether_1/fragment_0_1">
            <material>Gazebo/Red</material>
        </gazebo>

        <link name="tether_1/fragment_0_2">
            <visual>
                <origin rpy="0 0 0" xyz="0 0 0"/>
                <geometry>
                    <sphere radius="0.03"/>
                </geometry>
            </visual>
            <inertial>
                <mass value="0.05"/>
                <inertia ixx="0.000135" iyy="0.000135" izz="0.000135" ixy="0.0" ixz="0.0" iyz="0.0"/>
            </inertial>
        </link>
        <gazebo reference="tether_1/fragment_0_2">
            <material>Gazebo/Red</material>
        </gazebo>

        <link name="tether_1/fragment_0_3">
            <visual>
                <origin rpy="0 0 0" xyz="0 0 0"/>
                <geometry>
                    <sphere radius="0.03"/>
                </geometry>
            </visual>
            <inertial>
                <mass value="0.05"/>
                <inertia ixx="0.000135" iyy="0.000135" izz="0.000135" ixy="0.0" ixz="0.0" iyz="0.0"/>
            </inertial>
        </link>
        <gazebo reference="tether_1/fragment_0_3">
            <material>Gazebo/Red</material>
        </gazebo>
                
            <link name="tether_1/fragment_1_1">
            <visual>
                <origin rpy="0 0 0" xyz="0 0 0"/>
                <geometry>
                    <sphere radius="0.03"/>
                </geometry>
            </visual>
            <inertial>
                <mass value="0.05"/>
                <inertia ixx="0.000135" iyy="0.000135" izz="0.000135" ixy="0.0" ixz="0.0" iyz="0.0"/>
            </inertial>
        </link>
        <gazebo reference="tether_1/fragment_1_1">
            <material>Gazebo/Red</material>
        </gazebo>

        <link name="tether_1/fragment_1_2">
            <visual>
                <origin rpy="0 0 0" xyz="0 0 0"/>
                <geometry>
                    <sphere radius="0.03"/>
                </geometry>
            </visual>
            <inertial>
                <mass value="0.05"/>
                <inertia ixx="0.000135" iyy="0.000135" izz="0.000135" ixy="0.0" ixz="0.0" iyz="0.0"/>
            </inertial>
        </link>
        <gazebo reference="tether_1/fragment_1_2">
            <material>Gazebo/Red</material>
        </gazebo>

        <link name="tether_1/fragment_1_3">
            <visual>
                <origin rpy="0 0 0" xyz="0 0 0"/>
                <geometry>
                    <sphere radius="0.03"/>
                </geometry>
            </visual>
            <inertial>
                <mass value="0.05"/>
                <inertia ixx="0.000135" iyy="0.000135" izz="0.000135" ixy="0.0" ixz="0.0" iyz="0.0"/>
            </inertial>
        </link>
        <gazebo reference="tether_1/fragment_1_3">
            <material>Gazebo/Red</material>
        </gazebo>
                
                    <!--tether fragment joint-->
        <joint name="tether_1/joint_roll_1" type="continuous">
            <origin rpy="0 0 0" xyz="0 0 10.0"/>
            <parent link="tether_1/fragment_0_3"/>
            <child link="tether_1/fragment_1_1"/>
            <axis xyz="1 0 0" />
            <dynamics damping="1" friction="1"/>
        </joint>

        <joint name="tether_1/joint_pitch_1" type="continuous">
            <origin rpy="0 0 0" xyz="0 0 0"/>
            <parent link="tether_1/fragment_1_1"/>
            <child link="tether_1/fragment_1_2"/>
            <axis xyz="0 1 0" />
            <dynamics damping="1" friction="1"/>
        </joint>

        <joint name="tether_1/joint_yaw_1" type="continuous">
            <origin rpy="0 0 0" xyz="0 0 0"/>
            <parent link="tether_1/fragment_1_2"/>
            <child link="tether_1/fragment_1_3"/>
            <axis xyz="0 0 1" />
            <dynamics damping="1" friction="1"/>
        </joint>
                
            <link name="tether_1/rod">
            <visual>
                <origin rpy="0 0 0" xyz="0 0 0.1"/>
                <geometry>
                    <cylinder length="0.2" radius="0.01"/>
                </geometry>
            </visual>
            <inertial>
                <mass value="0.01"/>
                <inertia ixx="0.01" iyy="0.01" izz="0.01" ixy="0.0" ixz="0.0" iyz="0.0"/>
            </inertial>
            <collision>
                <geometry>
                    <cylinder length="0.2" radius="0.01"/>
                </geometry>
            </collision>
        </link>
        <gazebo reference="tether_1/rod">
            <material>Gazebo/Orange</material>
        </gazebo>
        <!--uav => tether joint-->
        <joint name="tether_1/rod_joint" type="fixed">
            <parent link="${namespace}/base_link"/>
            <child link="tether_1/rod"/>
            
                <origin rpy="${pi/2} 0 0" xyz="0 0 0"/>
            
        </joint>

        <joint name="tether_1/uav_roll_joint" type="continuous">
            <origin rpy="0 0 0" xyz="0 0 0.2"/>
            <parent link="tether_1/rod"/>
            <child link="tether_1/fragment_0_1"/>
            <axis xyz="1 0 0" />
            <dynamics damping="1" friction="1"/>
        </joint>

        <joint name="tether_1/uav_pitch_joint" type="continuous">
            <origin rpy="0 0 0" xyz="0 0 0"/>
            <parent link="tether_1/fragment_0_1"/>
            <child link="tether_1/fragment_0_2"/>
            <axis xyz="0 1 0" />
            <dynamics damping="1" friction="1"/>
        </joint>

        <joint name="tether_1/joint_yaw_joint" type="continuous">
            <origin rpy="0 0 0" xyz="0 0 0"/>
            <parent link="tether_1/fragment_0_2"/>
            <child link="tether_1/fragment_0_3"/>
            <axis xyz="0 0 1" />
            <dynamics damping="1" friction="1"/>
        </joint>
            <!--tether end joint-->
        <joint name="tether_1/ugv_joint_1" type="continuous">
            
                <origin rpy="${-pi/2} 0 0" xyz="0 0 10.0"/>
                <axis xyz="1 0 0" />
            
            <parent link="tether_1/fragment_1_3"/>
            <child link="mp_500_1/tether_end"/>
            <dynamics damping="1" friction="1"/>
        </joint>
        
            <link name="tether_2/fragment_0_1">
            <visual>
                <origin rpy="0 0 0" xyz="0 0 0"/>
                <geometry>
                    <sphere radius="0.03"/>
                </geometry>
            </visual>
            <inertial>
                <mass value="0.05"/>
                <inertia ixx="0.000135" iyy="0.000135" izz="0.000135" ixy="0.0" ixz="0.0" iyz="0.0"/>
            </inertial>
        </link>
        <gazebo reference="tether_2/fragment_0_1">
            <material>Gazebo/Red</material>
        </gazebo>

        <link name="tether_2/fragment_0_2">
            <visual>
                <origin rpy="0 0 0" xyz="0 0 0"/>
                <geometry>
                    <sphere radius="0.03"/>
                </geometry>
            </visual>
            <inertial>
                <mass value="0.05"/>
                <inertia ixx="0.000135" iyy="0.000135" izz="0.000135" ixy="0.0" ixz="0.0" iyz="0.0"/>
            </inertial>
        </link>
        <gazebo reference="tether_2/fragment_0_2">
            <material>Gazebo/Red</material>
        </gazebo>

        <link name="tether_2/fragment_0_3">
            <visual>
                <origin rpy="0 0 0" xyz="0 0 0"/>
                <geometry>
                    <sphere radius="0.03"/>
                </geometry>
            </visual>
            <inertial>
                <mass value="0.05"/>
                <inertia ixx="0.000135" iyy="0.000135" izz="0.000135" ixy="0.0" ixz="0.0" iyz="0.0"/>
            </inertial>
        </link>
        <gazebo reference="tether_2/fragment_0_3">
            <material>Gazebo/Red</material>
        </gazebo>
                
            <link name="tether_2/fragment_1_1">
            <visual>
                <origin rpy="0 0 0" xyz="0 0 0"/>
                <geometry>
                    <sphere radius="0.03"/>
                </geometry>
            </visual>
            <inertial>
                <mass value="0.05"/>
                <inertia ixx="0.000135" iyy="0.000135" izz="0.000135" ixy="0.0" ixz="0.0" iyz="0.0"/>
            </inertial>
        </link>
        <gazebo reference="tether_2/fragment_1_1">
            <material>Gazebo/Red</material>
        </gazebo>

        <link name="tether_2/fragment_1_2">
            <visual>
                <origin rpy="0 0 0" xyz="0 0 0"/>
                <geometry>
                    <sphere radius="0.03"/>
                </geometry>
            </visual>
            <inertial>
                <mass value="0.05"/>
                <inertia ixx="0.000135" iyy="0.000135" izz="0.000135" ixy="0.0" ixz="0.0" iyz="0.0"/>
            </inertial>
        </link>
        <gazebo reference="tether_2/fragment_1_2">
            <material>Gazebo/Red</material>
        </gazebo>

        <link name="tether_2/fragment_1_3">
            <visual>
                <origin rpy="0 0 0" xyz="0 0 0"/>
                <geometry>
                    <sphere radius="0.03"/>
                </geometry>
            </visual>
            <inertial>
                <mass value="0.05"/>
                <inertia ixx="0.000135" iyy="0.000135" izz="0.000135" ixy="0.0" ixz="0.0" iyz="0.0"/>
            </inertial>
        </link>
        <gazebo reference="tether_2/fragment_1_3">
            <material>Gazebo/Red</material>
        </gazebo>
                
                    <!--tether fragment joint-->
        <joint name="tether_2/joint_roll_1" type="continuous">
            <origin rpy="0 0 0" xyz="0 0 10.0"/>
            <parent link="tether_2/fragment_0_3"/>
            <child link="tether_2/fragment_1_1"/>
            <axis xyz="1 0 0" />
            <dynamics damping="1" friction="1"/>
        </joint>

        <joint name="tether_2/joint_pitch_1" type="continuous">
            <origin rpy="0 0 0" xyz="0 0 0"/>
            <parent link="tether_2/fragment_1_1"/>
            <child link="tether_2/fragment_1_2"/>
            <axis xyz="0 1 0" />
            <dynamics damping="1" friction="1"/>
        </joint>

        <joint name="tether_2/joint_yaw_1" type="continuous">
            <origin rpy="0 0 0" xyz="0 0 0"/>
            <parent link="tether_2/fragment_1_2"/>
            <child link="tether_2/fragment_1_3"/>
            <axis xyz="0 0 1" />
            <dynamics damping="1" friction="1"/>
        </joint>
                
            <link name="tether_2/rod">
            <visual>
                <origin rpy="0 0 0" xyz="0 0 0.1"/>
                <geometry>
                    <cylinder length="0.2" radius="0.01"/>
                </geometry>
            </visual>
            <inertial>
                <mass value="0.01"/>
                <inertia ixx="0.01" iyy="0.01" izz="0.01" ixy="0.0" ixz="0.0" iyz="0.0"/>
            </inertial>
            <collision>
                <geometry>
                    <cylinder length="0.2" radius="0.01"/>
                </geometry>
            </collision>
        </link>
        <gazebo reference="tether_2/rod">
            <material>Gazebo/Orange</material>
        </gazebo>
        <!--uav => tether joint-->
        <joint name="tether_2/rod_joint" type="fixed">
            <parent link="${namespace}/base_link"/>
            <child link="tether_2/rod"/>
            
                <origin rpy="0 ${-pi/2} 0" xyz="0 0 0"/>
            
        </joint>

        <joint name="tether_2/uav_roll_joint" type="continuous">
            <origin rpy="0 0 0" xyz="0 0 0.2"/>
            <parent link="tether_2/rod"/>
            <child link="tether_2/fragment_0_1"/>
            <axis xyz="1 0 0" />
            <dynamics damping="1" friction="1"/>
        </joint>

        <joint name="tether_2/uav_pitch_joint" type="continuous">
            <origin rpy="0 0 0" xyz="0 0 0"/>
            <parent link="tether_2/fragment_0_1"/>
            <child link="tether_2/fragment_0_2"/>
            <axis xyz="0 1 0" />
            <dynamics damping="1" friction="1"/>
        </joint>

        <joint name="tether_2/joint_yaw_joint" type="continuous">
            <origin rpy="0 0 0" xyz="0 0 0"/>
            <parent link="tether_2/fragment_0_2"/>
            <child link="tether_2/fragment_0_3"/>
            <axis xyz="0 0 1" />
            <dynamics damping="1" friction="1"/>
        </joint>
            <!--tether end joint-->
        <joint name="tether_2/ugv_joint_1" type="continuous">
            
                <origin rpy="0 ${pi/2} 0" xyz="0 0 10.0"/>
                <axis xyz="0 1 0" />
            
            <parent link="tether_2/fragment_1_3"/>
            <child link="mp_500_2/tether_end"/>
            <dynamics damping="1" friction="1"/>
        </joint>
        
            <link name="tether_3/fragment_0_1">
            <visual>
                <origin rpy="0 0 0" xyz="0 0 0"/>
                <geometry>
                    <sphere radius="0.03"/>
                </geometry>
            </visual>
            <inertial>
                <mass value="0.05"/>
                <inertia ixx="0.000135" iyy="0.000135" izz="0.000135" ixy="0.0" ixz="0.0" iyz="0.0"/>
            </inertial>
        </link>
        <gazebo reference="tether_3/fragment_0_1">
            <material>Gazebo/Red</material>
        </gazebo>

        <link name="tether_3/fragment_0_2">
            <visual>
                <origin rpy="0 0 0" xyz="0 0 0"/>
                <geometry>
                    <sphere radius="0.03"/>
                </geometry>
            </visual>
            <inertial>
                <mass value="0.05"/>
                <inertia ixx="0.000135" iyy="0.000135" izz="0.000135" ixy="0.0" ixz="0.0" iyz="0.0"/>
            </inertial>
        </link>
        <gazebo reference="tether_3/fragment_0_2">
            <material>Gazebo/Red</material>
        </gazebo>

        <link name="tether_3/fragment_0_3">
            <visual>
                <origin rpy="0 0 0" xyz="0 0 0"/>
                <geometry>
                    <sphere radius="0.03"/>
                </geometry>
            </visual>
            <inertial>
                <mass value="0.05"/>
                <inertia ixx="0.000135" iyy="0.000135" izz="0.000135" ixy="0.0" ixz="0.0" iyz="0.0"/>
            </inertial>
        </link>
        <gazebo reference="tether_3/fragment_0_3">
            <material>Gazebo/Red</material>
        </gazebo>
                
            <link name="tether_3/fragment_1_1">
            <visual>
                <origin rpy="0 0 0" xyz="0 0 0"/>
                <geometry>
                    <sphere radius="0.03"/>
                </geometry>
            </visual>
            <inertial>
                <mass value="0.05"/>
                <inertia ixx="0.000135" iyy="0.000135" izz="0.000135" ixy="0.0" ixz="0.0" iyz="0.0"/>
            </inertial>
        </link>
        <gazebo reference="tether_3/fragment_1_1">
            <material>Gazebo/Red</material>
        </gazebo>

        <link name="tether_3/fragment_1_2">
            <visual>
                <origin rpy="0 0 0" xyz="0 0 0"/>
                <geometry>
                    <sphere radius="0.03"/>
                </geometry>
            </visual>
            <inertial>
                <mass value="0.05"/>
                <inertia ixx="0.000135" iyy="0.000135" izz="0.000135" ixy="0.0" ixz="0.0" iyz="0.0"/>
            </inertial>
        </link>
        <gazebo reference="tether_3/fragment_1_2">
            <material>Gazebo/Red</material>
        </gazebo>

        <link name="tether_3/fragment_1_3">
            <visual>
                <origin rpy="0 0 0" xyz="0 0 0"/>
                <geometry>
                    <sphere radius="0.03"/>
                </geometry>
            </visual>
            <inertial>
                <mass value="0.05"/>
                <inertia ixx="0.000135" iyy="0.000135" izz="0.000135" ixy="0.0" ixz="0.0" iyz="0.0"/>
            </inertial>
        </link>
        <gazebo reference="tether_3/fragment_1_3">
            <material>Gazebo/Red</material>
        </gazebo>
                
                    <!--tether fragment joint-->
        <joint name="tether_3/joint_roll_1" type="continuous">
            <origin rpy="0 0 0" xyz="0 0 10.0"/>
            <parent link="tether_3/fragment_0_3"/>
            <child link="tether_3/fragment_1_1"/>
            <axis xyz="1 0 0" />
            <dynamics damping="1" friction="1"/>
        </joint>

        <joint name="tether_3/joint_pitch_1" type="continuous">
            <origin rpy="0 0 0" xyz="0 0 0"/>
            <parent link="tether_3/fragment_1_1"/>
            <child link="tether_3/fragment_1_2"/>
            <axis xyz="0 1 0" />
            <dynamics damping="1" friction="1"/>
        </joint>

        <joint name="tether_3/joint_yaw_1" type="continuous">
            <origin rpy="0 0 0" xyz="0 0 0"/>
            <parent link="tether_3/fragment_1_2"/>
            <child link="tether_3/fragment_1_3"/>
            <axis xyz="0 0 1" />
            <dynamics damping="1" friction="1"/>
        </joint>
                
            <link name="tether_3/rod">
            <visual>
                <origin rpy="0 0 0" xyz="0 0 0.1"/>
                <geometry>
                    <cylinder length="0.2" radius="0.01"/>
                </geometry>
            </visual>
            <inertial>
                <mass value="0.01"/>
                <inertia ixx="0.01" iyy="0.01" izz="0.01" ixy="0.0" ixz="0.0" iyz="0.0"/>
            </inertial>
            <collision>
                <geometry>
                    <cylinder length="0.2" radius="0.01"/>
                </geometry>
            </collision>
        </link>
        <gazebo reference="tether_3/rod">
            <material>Gazebo/Orange</material>
        </gazebo>
        <!--uav => tether joint-->
        <joint name="tether_3/rod_joint" type="fixed">
            <parent link="${namespace}/base_link"/>
            <child link="tether_3/rod"/>
            
                <origin rpy="${-pi/2} 0 0" xyz="0 0 0"/>
            
        </joint>

        <joint name="tether_3/uav_roll_joint" type="continuous">
            <origin rpy="0 0 0" xyz="0 0 0.2"/>
            <parent link="tether_3/rod"/>
            <child link="tether_3/fragment_0_1"/>
            <axis xyz="1 0 0" />
            <dynamics damping="1" friction="1"/>
        </joint>

        <joint name="tether_3/uav_pitch_joint" type="continuous">
            <origin rpy="0 0 0" xyz="0 0 0"/>
            <parent link="tether_3/fragment_0_1"/>
            <child link="tether_3/fragment_0_2"/>
            <axis xyz="0 1 0" />
            <dynamics damping="1" friction="1"/>
        </joint>

        <joint name="tether_3/joint_yaw_joint" type="continuous">
            <origin rpy="0 0 0" xyz="0 0 0"/>
            <parent link="tether_3/fragment_0_2"/>
            <child link="tether_3/fragment_0_3"/>
            <axis xyz="0 0 1" />
            <dynamics damping="1" friction="1"/>
        </joint>
            <!--tether end joint-->
        <joint name="tether_3/ugv_joint_1" type="continuous">
            
                <origin rpy="${pi/2} 0 0" xyz="0 0 10.0"/>
                <axis xyz="1 0 0" />
            
            <parent link="tether_3/fragment_1_3"/>
            <child link="mp_500_3/tether_end"/>
            <dynamics damping="1" friction="1"/>
        </joint>
        </xacro:macro>
</robot>