<?xml version="1.0"?>
<robot xmlns:xacro="http://ros.org/wiki/xacro">
    <!--tether model-->
    <xacro:macro name="tether">
        <!--tether fragment param--><!--joint dynamics--><!--link number--><!--tether_cylinder_joint--><!-- main-->
        
            <link name="tether_0/fragment_0">
            <visual>
                <origin rpy="0 0 0" xyz="0 0 0"/>
                <geometry>
                    <sphere radius="0.01"/>
                </geometry>
            </visual>
            <inertial>
                <mass value="0.1"/>
                <inertia ixx="3e-05" iyy="3e-05" izz="3e-05" ixy="0.0" ixz="0.0" iyz="0.0"/>
            </inertial>
            <collision>
                <geometry>
                    <sphere radius="0.01"/>
                </geometry>
            </collision>
        </link>
        <gazebo reference="tether_0/fragment_0">
            <material>Gazebo/Red</material>
        </gazebo>
                
            <link name="tether_0/fragment_1">
            <visual>
                <origin rpy="0 0 0" xyz="0 0 0"/>
                <geometry>
                    <sphere radius="0.01"/>
                </geometry>
            </visual>
            <inertial>
                <mass value="0.1"/>
                <inertia ixx="3e-05" iyy="3e-05" izz="3e-05" ixy="0.0" ixz="0.0" iyz="0.0"/>
            </inertial>
            <collision>
                <geometry>
                    <sphere radius="0.01"/>
                </geometry>
            </collision>
        </link>
        <gazebo reference="tether_0/fragment_1">
            <material>Gazebo/Red</material>
        </gazebo>
                
                    <!--tether fragment joint-->
        <joint name="tether_0/joint_1" type="continuous">
            <origin rpy="0 0 0" xyz="0 0 1.0"/>
            <parent link="tether_0/fragment_0"/>
            <child link="tether_0/fragment_1"/>
            <axis xyz="1 0 0" />
            <dynamics damping="0.1" friction="0.1"/>
        </joint>
                
            <link name="tether_0/fragment_2">
            <visual>
                <origin rpy="0 0 0" xyz="0 0 0"/>
                <geometry>
                    <sphere radius="0.01"/>
                </geometry>
            </visual>
            <inertial>
                <mass value="0.1"/>
                <inertia ixx="3e-05" iyy="3e-05" izz="3e-05" ixy="0.0" ixz="0.0" iyz="0.0"/>
            </inertial>
            <collision>
                <geometry>
                    <sphere radius="0.01"/>
                </geometry>
            </collision>
        </link>
        <gazebo reference="tether_0/fragment_2">
            <material>Gazebo/Red</material>
        </gazebo>
                
                    <!--tether fragment joint-->
        <joint name="tether_0/joint_2" type="continuous">
            <origin rpy="0 0 0" xyz="0 0 1.0"/>
            <parent link="tether_0/fragment_1"/>
            <child link="tether_0/fragment_2"/>
            <axis xyz="1 0 0" />
            <dynamics damping="0.1" friction="0.1"/>
        </joint>
                
            <link name="tether_0/fragment_3">
            <visual>
                <origin rpy="0 0 0" xyz="0 0 0"/>
                <geometry>
                    <sphere radius="0.01"/>
                </geometry>
            </visual>
            <inertial>
                <mass value="0.1"/>
                <inertia ixx="3e-05" iyy="3e-05" izz="3e-05" ixy="0.0" ixz="0.0" iyz="0.0"/>
            </inertial>
            <collision>
                <geometry>
                    <sphere radius="0.01"/>
                </geometry>
            </collision>
        </link>
        <gazebo reference="tether_0/fragment_3">
            <material>Gazebo/Red</material>
        </gazebo>
                
                    <!--tether fragment joint-->
        <joint name="tether_0/joint_3" type="continuous">
            <origin rpy="0 0 0" xyz="0 0 1.0"/>
            <parent link="tether_0/fragment_2"/>
            <child link="tether_0/fragment_3"/>
            <axis xyz="1 0 0" />
            <dynamics damping="0.1" friction="0.1"/>
        </joint>
                
            <link name="tether_0/fragment_4">
            <visual>
                <origin rpy="0 0 0" xyz="0 0 0"/>
                <geometry>
                    <sphere radius="0.01"/>
                </geometry>
            </visual>
            <inertial>
                <mass value="0.1"/>
                <inertia ixx="3e-05" iyy="3e-05" izz="3e-05" ixy="0.0" ixz="0.0" iyz="0.0"/>
            </inertial>
            <collision>
                <geometry>
                    <sphere radius="0.01"/>
                </geometry>
            </collision>
        </link>
        <gazebo reference="tether_0/fragment_4">
            <material>Gazebo/Red</material>
        </gazebo>
                
                    <!--tether fragment joint-->
        <joint name="tether_0/joint_4" type="continuous">
            <origin rpy="0 0 0" xyz="0 0 1.0"/>
            <parent link="tether_0/fragment_3"/>
            <child link="tether_0/fragment_4"/>
            <axis xyz="1 0 0" />
            <dynamics damping="0.1" friction="0.1"/>
        </joint>
                
            <!--uav => tether joint-->
        <joint name="tether_0/uav_joint" type="fixed">
            <parent link="${namespace}/base_link"/>
            <child link="tether_0/fragment_0"/>
            
                <origin rpy="0 ${pi/2} 0" xyz="0 0 0"/>
            
        </joint>
            <!--tether end joint-->
        <joint name="tether_0/ugv_joint_1" type="continuous">
            
                <origin rpy="0 ${-pi/2} 0" xyz="0 0 1.0"/>
            
            <parent link="tether_0/fragment_4"/>
            <child link="mp_500_0/tether_end"/>
            <axis xyz="1 0 0" />
            <dynamics damping="0.1" friction="0.1"/>
        </joint>
        
            <link name="tether_1/fragment_0">
            <visual>
                <origin rpy="0 0 0" xyz="0 0 0"/>
                <geometry>
                    <sphere radius="0.01"/>
                </geometry>
            </visual>
            <inertial>
                <mass value="0.1"/>
                <inertia ixx="3e-05" iyy="3e-05" izz="3e-05" ixy="0.0" ixz="0.0" iyz="0.0"/>
            </inertial>
            <collision>
                <geometry>
                    <sphere radius="0.01"/>
                </geometry>
            </collision>
        </link>
        <gazebo reference="tether_1/fragment_0">
            <material>Gazebo/Red</material>
        </gazebo>
                
            <link name="tether_1/fragment_1">
            <visual>
                <origin rpy="0 0 0" xyz="0 0 0"/>
                <geometry>
                    <sphere radius="0.01"/>
                </geometry>
            </visual>
            <inertial>
                <mass value="0.1"/>
                <inertia ixx="3e-05" iyy="3e-05" izz="3e-05" ixy="0.0" ixz="0.0" iyz="0.0"/>
            </inertial>
            <collision>
                <geometry>
                    <sphere radius="0.01"/>
                </geometry>
            </collision>
        </link>
        <gazebo reference="tether_1/fragment_1">
            <material>Gazebo/Red</material>
        </gazebo>
                
                    <!--tether fragment joint-->
        <joint name="tether_1/joint_1" type="continuous">
            <origin rpy="0 0 0" xyz="0 0 1.0"/>
            <parent link="tether_1/fragment_0"/>
            <child link="tether_1/fragment_1"/>
            <axis xyz="1 0 0" />
            <dynamics damping="0.1" friction="0.1"/>
        </joint>
                
            <link name="tether_1/fragment_2">
            <visual>
                <origin rpy="0 0 0" xyz="0 0 0"/>
                <geometry>
                    <sphere radius="0.01"/>
                </geometry>
            </visual>
            <inertial>
                <mass value="0.1"/>
                <inertia ixx="3e-05" iyy="3e-05" izz="3e-05" ixy="0.0" ixz="0.0" iyz="0.0"/>
            </inertial>
            <collision>
                <geometry>
                    <sphere radius="0.01"/>
                </geometry>
            </collision>
        </link>
        <gazebo reference="tether_1/fragment_2">
            <material>Gazebo/Red</material>
        </gazebo>
                
                    <!--tether fragment joint-->
        <joint name="tether_1/joint_2" type="continuous">
            <origin rpy="0 0 0" xyz="0 0 1.0"/>
            <parent link="tether_1/fragment_1"/>
            <child link="tether_1/fragment_2"/>
            <axis xyz="1 0 0" />
            <dynamics damping="0.1" friction="0.1"/>
        </joint>
                
            <link name="tether_1/fragment_3">
            <visual>
                <origin rpy="0 0 0" xyz="0 0 0"/>
                <geometry>
                    <sphere radius="0.01"/>
                </geometry>
            </visual>
            <inertial>
                <mass value="0.1"/>
                <inertia ixx="3e-05" iyy="3e-05" izz="3e-05" ixy="0.0" ixz="0.0" iyz="0.0"/>
            </inertial>
            <collision>
                <geometry>
                    <sphere radius="0.01"/>
                </geometry>
            </collision>
        </link>
        <gazebo reference="tether_1/fragment_3">
            <material>Gazebo/Red</material>
        </gazebo>
                
                    <!--tether fragment joint-->
        <joint name="tether_1/joint_3" type="continuous">
            <origin rpy="0 0 0" xyz="0 0 1.0"/>
            <parent link="tether_1/fragment_2"/>
            <child link="tether_1/fragment_3"/>
            <axis xyz="1 0 0" />
            <dynamics damping="0.1" friction="0.1"/>
        </joint>
                
            <link name="tether_1/fragment_4">
            <visual>
                <origin rpy="0 0 0" xyz="0 0 0"/>
                <geometry>
                    <sphere radius="0.01"/>
                </geometry>
            </visual>
            <inertial>
                <mass value="0.1"/>
                <inertia ixx="3e-05" iyy="3e-05" izz="3e-05" ixy="0.0" ixz="0.0" iyz="0.0"/>
            </inertial>
            <collision>
                <geometry>
                    <sphere radius="0.01"/>
                </geometry>
            </collision>
        </link>
        <gazebo reference="tether_1/fragment_4">
            <material>Gazebo/Red</material>
        </gazebo>
                
                    <!--tether fragment joint-->
        <joint name="tether_1/joint_4" type="continuous">
            <origin rpy="0 0 0" xyz="0 0 1.0"/>
            <parent link="tether_1/fragment_3"/>
            <child link="tether_1/fragment_4"/>
            <axis xyz="1 0 0" />
            <dynamics damping="0.1" friction="0.1"/>
        </joint>
                
            <!--uav => tether joint-->
        <joint name="tether_1/uav_joint" type="fixed">
            <parent link="${namespace}/base_link"/>
            <child link="tether_1/fragment_0"/>
            
                <origin rpy="${pi/2} 0 0" xyz="0 0 0"/>
            
        </joint>
            <!--tether end joint-->
        <joint name="tether_1/ugv_joint_1" type="continuous">
            
                <origin rpy="${-pi/2} 0 0" xyz="0 0 1.0"/>
            
            <parent link="tether_1/fragment_4"/>
            <child link="mp_500_1/tether_end"/>
            <axis xyz="1 0 0" />
            <dynamics damping="0.1" friction="0.1"/>
        </joint>
        
            <link name="tether_2/fragment_0">
            <visual>
                <origin rpy="0 0 0" xyz="0 0 0"/>
                <geometry>
                    <sphere radius="0.01"/>
                </geometry>
            </visual>
            <inertial>
                <mass value="0.1"/>
                <inertia ixx="3e-05" iyy="3e-05" izz="3e-05" ixy="0.0" ixz="0.0" iyz="0.0"/>
            </inertial>
            <collision>
                <geometry>
                    <sphere radius="0.01"/>
                </geometry>
            </collision>
        </link>
        <gazebo reference="tether_2/fragment_0">
            <material>Gazebo/Red</material>
        </gazebo>
                
            <link name="tether_2/fragment_1">
            <visual>
                <origin rpy="0 0 0" xyz="0 0 0"/>
                <geometry>
                    <sphere radius="0.01"/>
                </geometry>
            </visual>
            <inertial>
                <mass value="0.1"/>
                <inertia ixx="3e-05" iyy="3e-05" izz="3e-05" ixy="0.0" ixz="0.0" iyz="0.0"/>
            </inertial>
            <collision>
                <geometry>
                    <sphere radius="0.01"/>
                </geometry>
            </collision>
        </link>
        <gazebo reference="tether_2/fragment_1">
            <material>Gazebo/Red</material>
        </gazebo>
                
                    <!--tether fragment joint-->
        <joint name="tether_2/joint_1" type="continuous">
            <origin rpy="0 0 0" xyz="0 0 1.0"/>
            <parent link="tether_2/fragment_0"/>
            <child link="tether_2/fragment_1"/>
            <axis xyz="1 0 0" />
            <dynamics damping="0.1" friction="0.1"/>
        </joint>
                
            <link name="tether_2/fragment_2">
            <visual>
                <origin rpy="0 0 0" xyz="0 0 0"/>
                <geometry>
                    <sphere radius="0.01"/>
                </geometry>
            </visual>
            <inertial>
                <mass value="0.1"/>
                <inertia ixx="3e-05" iyy="3e-05" izz="3e-05" ixy="0.0" ixz="0.0" iyz="0.0"/>
            </inertial>
            <collision>
                <geometry>
                    <sphere radius="0.01"/>
                </geometry>
            </collision>
        </link>
        <gazebo reference="tether_2/fragment_2">
            <material>Gazebo/Red</material>
        </gazebo>
                
                    <!--tether fragment joint-->
        <joint name="tether_2/joint_2" type="continuous">
            <origin rpy="0 0 0" xyz="0 0 1.0"/>
            <parent link="tether_2/fragment_1"/>
            <child link="tether_2/fragment_2"/>
            <axis xyz="1 0 0" />
            <dynamics damping="0.1" friction="0.1"/>
        </joint>
                
            <link name="tether_2/fragment_3">
            <visual>
                <origin rpy="0 0 0" xyz="0 0 0"/>
                <geometry>
                    <sphere radius="0.01"/>
                </geometry>
            </visual>
            <inertial>
                <mass value="0.1"/>
                <inertia ixx="3e-05" iyy="3e-05" izz="3e-05" ixy="0.0" ixz="0.0" iyz="0.0"/>
            </inertial>
            <collision>
                <geometry>
                    <sphere radius="0.01"/>
                </geometry>
            </collision>
        </link>
        <gazebo reference="tether_2/fragment_3">
            <material>Gazebo/Red</material>
        </gazebo>
                
                    <!--tether fragment joint-->
        <joint name="tether_2/joint_3" type="continuous">
            <origin rpy="0 0 0" xyz="0 0 1.0"/>
            <parent link="tether_2/fragment_2"/>
            <child link="tether_2/fragment_3"/>
            <axis xyz="1 0 0" />
            <dynamics damping="0.1" friction="0.1"/>
        </joint>
                
            <link name="tether_2/fragment_4">
            <visual>
                <origin rpy="0 0 0" xyz="0 0 0"/>
                <geometry>
                    <sphere radius="0.01"/>
                </geometry>
            </visual>
            <inertial>
                <mass value="0.1"/>
                <inertia ixx="3e-05" iyy="3e-05" izz="3e-05" ixy="0.0" ixz="0.0" iyz="0.0"/>
            </inertial>
            <collision>
                <geometry>
                    <sphere radius="0.01"/>
                </geometry>
            </collision>
        </link>
        <gazebo reference="tether_2/fragment_4">
            <material>Gazebo/Red</material>
        </gazebo>
                
                    <!--tether fragment joint-->
        <joint name="tether_2/joint_4" type="continuous">
            <origin rpy="0 0 0" xyz="0 0 1.0"/>
            <parent link="tether_2/fragment_3"/>
            <child link="tether_2/fragment_4"/>
            <axis xyz="1 0 0" />
            <dynamics damping="0.1" friction="0.1"/>
        </joint>
                
            <!--uav => tether joint-->
        <joint name="tether_2/uav_joint" type="fixed">
            <parent link="${namespace}/base_link"/>
            <child link="tether_2/fragment_0"/>
            
                <origin rpy="0 ${-pi/2} 0" xyz="0 0 0"/>
            
        </joint>
            <!--tether end joint-->
        <joint name="tether_2/ugv_joint_1" type="continuous">
            
                <origin rpy="0 ${pi/2} 0" xyz="0 0 1.0"/>
            
            <parent link="tether_2/fragment_4"/>
            <child link="mp_500_2/tether_end"/>
            <axis xyz="1 0 0" />
            <dynamics damping="0.1" friction="0.1"/>
        </joint>
        
            <link name="tether_3/fragment_0">
            <visual>
                <origin rpy="0 0 0" xyz="0 0 0"/>
                <geometry>
                    <sphere radius="0.01"/>
                </geometry>
            </visual>
            <inertial>
                <mass value="0.1"/>
                <inertia ixx="3e-05" iyy="3e-05" izz="3e-05" ixy="0.0" ixz="0.0" iyz="0.0"/>
            </inertial>
            <collision>
                <geometry>
                    <sphere radius="0.01"/>
                </geometry>
            </collision>
        </link>
        <gazebo reference="tether_3/fragment_0">
            <material>Gazebo/Red</material>
        </gazebo>
                
            <link name="tether_3/fragment_1">
            <visual>
                <origin rpy="0 0 0" xyz="0 0 0"/>
                <geometry>
                    <sphere radius="0.01"/>
                </geometry>
            </visual>
            <inertial>
                <mass value="0.1"/>
                <inertia ixx="3e-05" iyy="3e-05" izz="3e-05" ixy="0.0" ixz="0.0" iyz="0.0"/>
            </inertial>
            <collision>
                <geometry>
                    <sphere radius="0.01"/>
                </geometry>
            </collision>
        </link>
        <gazebo reference="tether_3/fragment_1">
            <material>Gazebo/Red</material>
        </gazebo>
                
                    <!--tether fragment joint-->
        <joint name="tether_3/joint_1" type="continuous">
            <origin rpy="0 0 0" xyz="0 0 1.0"/>
            <parent link="tether_3/fragment_0"/>
            <child link="tether_3/fragment_1"/>
            <axis xyz="1 0 0" />
            <dynamics damping="0.1" friction="0.1"/>
        </joint>
                
            <link name="tether_3/fragment_2">
            <visual>
                <origin rpy="0 0 0" xyz="0 0 0"/>
                <geometry>
                    <sphere radius="0.01"/>
                </geometry>
            </visual>
            <inertial>
                <mass value="0.1"/>
                <inertia ixx="3e-05" iyy="3e-05" izz="3e-05" ixy="0.0" ixz="0.0" iyz="0.0"/>
            </inertial>
            <collision>
                <geometry>
                    <sphere radius="0.01"/>
                </geometry>
            </collision>
        </link>
        <gazebo reference="tether_3/fragment_2">
            <material>Gazebo/Red</material>
        </gazebo>
                
                    <!--tether fragment joint-->
        <joint name="tether_3/joint_2" type="continuous">
            <origin rpy="0 0 0" xyz="0 0 1.0"/>
            <parent link="tether_3/fragment_1"/>
            <child link="tether_3/fragment_2"/>
            <axis xyz="1 0 0" />
            <dynamics damping="0.1" friction="0.1"/>
        </joint>
                
            <link name="tether_3/fragment_3">
            <visual>
                <origin rpy="0 0 0" xyz="0 0 0"/>
                <geometry>
                    <sphere radius="0.01"/>
                </geometry>
            </visual>
            <inertial>
                <mass value="0.1"/>
                <inertia ixx="3e-05" iyy="3e-05" izz="3e-05" ixy="0.0" ixz="0.0" iyz="0.0"/>
            </inertial>
            <collision>
                <geometry>
                    <sphere radius="0.01"/>
                </geometry>
            </collision>
        </link>
        <gazebo reference="tether_3/fragment_3">
            <material>Gazebo/Red</material>
        </gazebo>
                
                    <!--tether fragment joint-->
        <joint name="tether_3/joint_3" type="continuous">
            <origin rpy="0 0 0" xyz="0 0 1.0"/>
            <parent link="tether_3/fragment_2"/>
            <child link="tether_3/fragment_3"/>
            <axis xyz="1 0 0" />
            <dynamics damping="0.1" friction="0.1"/>
        </joint>
                
            <link name="tether_3/fragment_4">
            <visual>
                <origin rpy="0 0 0" xyz="0 0 0"/>
                <geometry>
                    <sphere radius="0.01"/>
                </geometry>
            </visual>
            <inertial>
                <mass value="0.1"/>
                <inertia ixx="3e-05" iyy="3e-05" izz="3e-05" ixy="0.0" ixz="0.0" iyz="0.0"/>
            </inertial>
            <collision>
                <geometry>
                    <sphere radius="0.01"/>
                </geometry>
            </collision>
        </link>
        <gazebo reference="tether_3/fragment_4">
            <material>Gazebo/Red</material>
        </gazebo>
                
                    <!--tether fragment joint-->
        <joint name="tether_3/joint_4" type="continuous">
            <origin rpy="0 0 0" xyz="0 0 1.0"/>
            <parent link="tether_3/fragment_3"/>
            <child link="tether_3/fragment_4"/>
            <axis xyz="1 0 0" />
            <dynamics damping="0.1" friction="0.1"/>
        </joint>
                
            <!--uav => tether joint-->
        <joint name="tether_3/uav_joint" type="fixed">
            <parent link="${namespace}/base_link"/>
            <child link="tether_3/fragment_0"/>
            
                <origin rpy="${-pi/2} 0 0" xyz="0 0 0"/>
            
        </joint>
            <!--tether end joint-->
        <joint name="tether_3/ugv_joint_1" type="continuous">
            
                <origin rpy="${pi/2} 0 0" xyz="0 0 1.0"/>
            
            <parent link="tether_3/fragment_4"/>
            <child link="mp_500_3/tether_end"/>
            <axis xyz="1 0 0" />
            <dynamics damping="0.1" friction="0.1"/>
        </joint>
        </xacro:macro>
</robot>