<?xml version="1.0"?>
<robot xmlns:xacro="http://ros.org/wiki/xacro">
    <!--tether model-->
    <xacro:macro name="tether">
        <!--tether fragment param--><!--small link inatial--><!--link number--><!--tether_cylinder_joint--><!-- main-->
        <link name="tether_fragment_0">
            <visual>
                <origin rpy="0 0 0" xyz="0 0 0.05"/>
                <geometry>
                    <cylinder length="0.1" radius="0.001"/>
                </geometry>
                <!--material name="black"/-->
            </visual>
            <inertial>
                <mass value="0.0001"/>
                <inertia ixx="8.33583333333e-08" iyy="8.33583333333e-08" izz="5e-11" ixy="0.0" ixz="0.0" iyz="0.0"/>
            </inertial>
        </link>
            
        <link name="tether_fragment_1">
            <visual>
                <origin rpy="0 0 0" xyz="0 0 0.05"/>
                <geometry>
                    <cylinder length="0.1" radius="0.001"/>
                </geometry>
                <!--material name="black"/-->
            </visual>
            <inertial>
                <mass value="0.0001"/>
                <inertia ixx="8.33583333333e-08" iyy="8.33583333333e-08" izz="5e-11" ixy="0.0" ixz="0.0" iyz="0.0"/>
            </inertial>
        </link>
            
                <!--link between two tether fragments-->
        <link name="small_link_1_1">
            <inertial>
                <mass value="1e-05"/>
                <inertia ixx="1e-05" iyy="1e-05" izz="1e-05" ixy="0.0" ixz="0.0" iyz="0.0"/>
            </inertial>
        </link>
        <link name="small_link_2_1">
            <inertial>
                <mass value="1e-05"/>
                <inertia ixx="1e-05" iyy="1e-05" izz="1e-05" ixy="0.0" ixz="0.0" iyz="0.0"/>
            </inertial>
        </link>

        <!--tether fragment joint-->
        <joint name="joint_1_1" type="continuous">
            <origin rpy="0 0 0" xyz="0 0 0.1"/>
            <parent link="tether_fragment_0"/>
            <child link="small_link_1_1"/>
            <axis xyz="1 0 0" />
        </joint>
        <joint name="joint_2_1" type="continuous">
            <parent link="small_link_1_1"/>
            <child link="small_link_2_1"/>
            <axis xyz="0 1 0" />
        </joint>
        <joint name="joint_1_1_" type="continuous">
            <parent link="small_link_2_1"/>
            <child link="tether_fragment_1"/>
            <axis xyz="0 0 1" />
        </joint>
            
        <link name="tether_fragment_2">
            <visual>
                <origin rpy="0 0 0" xyz="0 0 0.05"/>
                <geometry>
                    <cylinder length="0.1" radius="0.001"/>
                </geometry>
                <!--material name="black"/-->
            </visual>
            <inertial>
                <mass value="0.0001"/>
                <inertia ixx="8.33583333333e-08" iyy="8.33583333333e-08" izz="5e-11" ixy="0.0" ixz="0.0" iyz="0.0"/>
            </inertial>
        </link>
            
                <!--link between two tether fragments-->
        <link name="small_link_1_2">
            <inertial>
                <mass value="1e-05"/>
                <inertia ixx="1e-05" iyy="1e-05" izz="1e-05" ixy="0.0" ixz="0.0" iyz="0.0"/>
            </inertial>
        </link>
        <link name="small_link_2_2">
            <inertial>
                <mass value="1e-05"/>
                <inertia ixx="1e-05" iyy="1e-05" izz="1e-05" ixy="0.0" ixz="0.0" iyz="0.0"/>
            </inertial>
        </link>

        <!--tether fragment joint-->
        <joint name="joint_1_2" type="continuous">
            <origin rpy="0 0 0" xyz="0 0 0.1"/>
            <parent link="tether_fragment_1"/>
            <child link="small_link_1_2"/>
            <axis xyz="1 0 0" />
        </joint>
        <joint name="joint_2_2" type="continuous">
            <parent link="small_link_1_2"/>
            <child link="small_link_2_2"/>
            <axis xyz="0 1 0" />
        </joint>
        <joint name="joint_1_2_" type="continuous">
            <parent link="small_link_2_2"/>
            <child link="tether_fragment_2"/>
            <axis xyz="0 0 1" />
        </joint>
            
        <link name="tether_fragment_3">
            <visual>
                <origin rpy="0 0 0" xyz="0 0 0.05"/>
                <geometry>
                    <cylinder length="0.1" radius="0.001"/>
                </geometry>
                <!--material name="black"/-->
            </visual>
            <inertial>
                <mass value="0.0001"/>
                <inertia ixx="8.33583333333e-08" iyy="8.33583333333e-08" izz="5e-11" ixy="0.0" ixz="0.0" iyz="0.0"/>
            </inertial>
        </link>
            
                <!--link between two tether fragments-->
        <link name="small_link_1_3">
            <inertial>
                <mass value="1e-05"/>
                <inertia ixx="1e-05" iyy="1e-05" izz="1e-05" ixy="0.0" ixz="0.0" iyz="0.0"/>
            </inertial>
        </link>
        <link name="small_link_2_3">
            <inertial>
                <mass value="1e-05"/>
                <inertia ixx="1e-05" iyy="1e-05" izz="1e-05" ixy="0.0" ixz="0.0" iyz="0.0"/>
            </inertial>
        </link>

        <!--tether fragment joint-->
        <joint name="joint_1_3" type="continuous">
            <origin rpy="0 0 0" xyz="0 0 0.1"/>
            <parent link="tether_fragment_2"/>
            <child link="small_link_1_3"/>
            <axis xyz="1 0 0" />
        </joint>
        <joint name="joint_2_3" type="continuous">
            <parent link="small_link_1_3"/>
            <child link="small_link_2_3"/>
            <axis xyz="0 1 0" />
        </joint>
        <joint name="joint_1_3_" type="continuous">
            <parent link="small_link_2_3"/>
            <child link="tether_fragment_3"/>
            <axis xyz="0 0 1" />
        </joint>
            
        <link name="tether_fragment_4">
            <visual>
                <origin rpy="0 0 0" xyz="0 0 0.05"/>
                <geometry>
                    <cylinder length="0.1" radius="0.001"/>
                </geometry>
                <!--material name="black"/-->
            </visual>
            <inertial>
                <mass value="0.0001"/>
                <inertia ixx="8.33583333333e-08" iyy="8.33583333333e-08" izz="5e-11" ixy="0.0" ixz="0.0" iyz="0.0"/>
            </inertial>
        </link>
            
                <!--link between two tether fragments-->
        <link name="small_link_1_4">
            <inertial>
                <mass value="1e-05"/>
                <inertia ixx="1e-05" iyy="1e-05" izz="1e-05" ixy="0.0" ixz="0.0" iyz="0.0"/>
            </inertial>
        </link>
        <link name="small_link_2_4">
            <inertial>
                <mass value="1e-05"/>
                <inertia ixx="1e-05" iyy="1e-05" izz="1e-05" ixy="0.0" ixz="0.0" iyz="0.0"/>
            </inertial>
        </link>

        <!--tether fragment joint-->
        <joint name="joint_1_4" type="continuous">
            <origin rpy="0 0 0" xyz="0 0 0.1"/>
            <parent link="tether_fragment_3"/>
            <child link="small_link_1_4"/>
            <axis xyz="1 0 0" />
        </joint>
        <joint name="joint_2_4" type="continuous">
            <parent link="small_link_1_4"/>
            <child link="small_link_2_4"/>
            <axis xyz="0 1 0" />
        </joint>
        <joint name="joint_1_4_" type="continuous">
            <parent link="small_link_2_4"/>
            <child link="tether_fragment_4"/>
            <axis xyz="0 0 1" />
        </joint>
            
        <link name="tether_fragment_5">
            <visual>
                <origin rpy="0 0 0" xyz="0 0 0.05"/>
                <geometry>
                    <cylinder length="0.1" radius="0.001"/>
                </geometry>
                <!--material name="black"/-->
            </visual>
            <inertial>
                <mass value="0.0001"/>
                <inertia ixx="8.33583333333e-08" iyy="8.33583333333e-08" izz="5e-11" ixy="0.0" ixz="0.0" iyz="0.0"/>
            </inertial>
        </link>
            
                <!--link between two tether fragments-->
        <link name="small_link_1_5">
            <inertial>
                <mass value="1e-05"/>
                <inertia ixx="1e-05" iyy="1e-05" izz="1e-05" ixy="0.0" ixz="0.0" iyz="0.0"/>
            </inertial>
        </link>
        <link name="small_link_2_5">
            <inertial>
                <mass value="1e-05"/>
                <inertia ixx="1e-05" iyy="1e-05" izz="1e-05" ixy="0.0" ixz="0.0" iyz="0.0"/>
            </inertial>
        </link>

        <!--tether fragment joint-->
        <joint name="joint_1_5" type="continuous">
            <origin rpy="0 0 0" xyz="0 0 0.1"/>
            <parent link="tether_fragment_4"/>
            <child link="small_link_1_5"/>
            <axis xyz="1 0 0" />
        </joint>
        <joint name="joint_2_5" type="continuous">
            <parent link="small_link_1_5"/>
            <child link="small_link_2_5"/>
            <axis xyz="0 1 0" />
        </joint>
        <joint name="joint_1_5_" type="continuous">
            <parent link="small_link_2_5"/>
            <child link="tether_fragment_5"/>
            <axis xyz="0 0 1" />
        </joint>
            
        <link name="tether_fragment_6">
            <visual>
                <origin rpy="0 0 0" xyz="0 0 0.05"/>
                <geometry>
                    <cylinder length="0.1" radius="0.001"/>
                </geometry>
                <!--material name="black"/-->
            </visual>
            <inertial>
                <mass value="0.0001"/>
                <inertia ixx="8.33583333333e-08" iyy="8.33583333333e-08" izz="5e-11" ixy="0.0" ixz="0.0" iyz="0.0"/>
            </inertial>
        </link>
            
                <!--link between two tether fragments-->
        <link name="small_link_1_6">
            <inertial>
                <mass value="1e-05"/>
                <inertia ixx="1e-05" iyy="1e-05" izz="1e-05" ixy="0.0" ixz="0.0" iyz="0.0"/>
            </inertial>
        </link>
        <link name="small_link_2_6">
            <inertial>
                <mass value="1e-05"/>
                <inertia ixx="1e-05" iyy="1e-05" izz="1e-05" ixy="0.0" ixz="0.0" iyz="0.0"/>
            </inertial>
        </link>

        <!--tether fragment joint-->
        <joint name="joint_1_6" type="continuous">
            <origin rpy="0 0 0" xyz="0 0 0.1"/>
            <parent link="tether_fragment_5"/>
            <child link="small_link_1_6"/>
            <axis xyz="1 0 0" />
        </joint>
        <joint name="joint_2_6" type="continuous">
            <parent link="small_link_1_6"/>
            <child link="small_link_2_6"/>
            <axis xyz="0 1 0" />
        </joint>
        <joint name="joint_1_6_" type="continuous">
            <parent link="small_link_2_6"/>
            <child link="tether_fragment_6"/>
            <axis xyz="0 0 1" />
        </joint>
            
        <link name="tether_fragment_7">
            <visual>
                <origin rpy="0 0 0" xyz="0 0 0.05"/>
                <geometry>
                    <cylinder length="0.1" radius="0.001"/>
                </geometry>
                <!--material name="black"/-->
            </visual>
            <inertial>
                <mass value="0.0001"/>
                <inertia ixx="8.33583333333e-08" iyy="8.33583333333e-08" izz="5e-11" ixy="0.0" ixz="0.0" iyz="0.0"/>
            </inertial>
        </link>
            
                <!--link between two tether fragments-->
        <link name="small_link_1_7">
            <inertial>
                <mass value="1e-05"/>
                <inertia ixx="1e-05" iyy="1e-05" izz="1e-05" ixy="0.0" ixz="0.0" iyz="0.0"/>
            </inertial>
        </link>
        <link name="small_link_2_7">
            <inertial>
                <mass value="1e-05"/>
                <inertia ixx="1e-05" iyy="1e-05" izz="1e-05" ixy="0.0" ixz="0.0" iyz="0.0"/>
            </inertial>
        </link>

        <!--tether fragment joint-->
        <joint name="joint_1_7" type="continuous">
            <origin rpy="0 0 0" xyz="0 0 0.1"/>
            <parent link="tether_fragment_6"/>
            <child link="small_link_1_7"/>
            <axis xyz="1 0 0" />
        </joint>
        <joint name="joint_2_7" type="continuous">
            <parent link="small_link_1_7"/>
            <child link="small_link_2_7"/>
            <axis xyz="0 1 0" />
        </joint>
        <joint name="joint_1_7_" type="continuous">
            <parent link="small_link_2_7"/>
            <child link="tether_fragment_7"/>
            <axis xyz="0 0 1" />
        </joint>
            
        <link name="tether_fragment_8">
            <visual>
                <origin rpy="0 0 0" xyz="0 0 0.05"/>
                <geometry>
                    <cylinder length="0.1" radius="0.001"/>
                </geometry>
                <!--material name="black"/-->
            </visual>
            <inertial>
                <mass value="0.0001"/>
                <inertia ixx="8.33583333333e-08" iyy="8.33583333333e-08" izz="5e-11" ixy="0.0" ixz="0.0" iyz="0.0"/>
            </inertial>
        </link>
            
                <!--link between two tether fragments-->
        <link name="small_link_1_8">
            <inertial>
                <mass value="1e-05"/>
                <inertia ixx="1e-05" iyy="1e-05" izz="1e-05" ixy="0.0" ixz="0.0" iyz="0.0"/>
            </inertial>
        </link>
        <link name="small_link_2_8">
            <inertial>
                <mass value="1e-05"/>
                <inertia ixx="1e-05" iyy="1e-05" izz="1e-05" ixy="0.0" ixz="0.0" iyz="0.0"/>
            </inertial>
        </link>

        <!--tether fragment joint-->
        <joint name="joint_1_8" type="continuous">
            <origin rpy="0 0 0" xyz="0 0 0.1"/>
            <parent link="tether_fragment_7"/>
            <child link="small_link_1_8"/>
            <axis xyz="1 0 0" />
        </joint>
        <joint name="joint_2_8" type="continuous">
            <parent link="small_link_1_8"/>
            <child link="small_link_2_8"/>
            <axis xyz="0 1 0" />
        </joint>
        <joint name="joint_1_8_" type="continuous">
            <parent link="small_link_2_8"/>
            <child link="tether_fragment_8"/>
            <axis xyz="0 0 1" />
        </joint>
            
        <link name="tether_fragment_9">
            <visual>
                <origin rpy="0 0 0" xyz="0 0 0.05"/>
                <geometry>
                    <cylinder length="0.1" radius="0.001"/>
                </geometry>
                <!--material name="black"/-->
            </visual>
            <inertial>
                <mass value="0.0001"/>
                <inertia ixx="8.33583333333e-08" iyy="8.33583333333e-08" izz="5e-11" ixy="0.0" ixz="0.0" iyz="0.0"/>
            </inertial>
        </link>
            
                <!--link between two tether fragments-->
        <link name="small_link_1_9">
            <inertial>
                <mass value="1e-05"/>
                <inertia ixx="1e-05" iyy="1e-05" izz="1e-05" ixy="0.0" ixz="0.0" iyz="0.0"/>
            </inertial>
        </link>
        <link name="small_link_2_9">
            <inertial>
                <mass value="1e-05"/>
                <inertia ixx="1e-05" iyy="1e-05" izz="1e-05" ixy="0.0" ixz="0.0" iyz="0.0"/>
            </inertial>
        </link>

        <!--tether fragment joint-->
        <joint name="joint_1_9" type="continuous">
            <origin rpy="0 0 0" xyz="0 0 0.1"/>
            <parent link="tether_fragment_8"/>
            <child link="small_link_1_9"/>
            <axis xyz="1 0 0" />
        </joint>
        <joint name="joint_2_9" type="continuous">
            <parent link="small_link_1_9"/>
            <child link="small_link_2_9"/>
            <axis xyz="0 1 0" />
        </joint>
        <joint name="joint_1_9_" type="continuous">
            <parent link="small_link_2_9"/>
            <child link="tether_fragment_9"/>
            <axis xyz="0 0 1" />
        </joint>
            
        <link name="tether_fragment_10">
            <visual>
                <origin rpy="0 0 0" xyz="0 0 0.05"/>
                <geometry>
                    <cylinder length="0.1" radius="0.001"/>
                </geometry>
                <!--material name="black"/-->
            </visual>
            <inertial>
                <mass value="0.0001"/>
                <inertia ixx="8.33583333333e-08" iyy="8.33583333333e-08" izz="5e-11" ixy="0.0" ixz="0.0" iyz="0.0"/>
            </inertial>
        </link>
            
                <!--link between two tether fragments-->
        <link name="small_link_1_10">
            <inertial>
                <mass value="1e-05"/>
                <inertia ixx="1e-05" iyy="1e-05" izz="1e-05" ixy="0.0" ixz="0.0" iyz="0.0"/>
            </inertial>
        </link>
        <link name="small_link_2_10">
            <inertial>
                <mass value="1e-05"/>
                <inertia ixx="1e-05" iyy="1e-05" izz="1e-05" ixy="0.0" ixz="0.0" iyz="0.0"/>
            </inertial>
        </link>

        <!--tether fragment joint-->
        <joint name="joint_1_10" type="continuous">
            <origin rpy="0 0 0" xyz="0 0 0.1"/>
            <parent link="tether_fragment_9"/>
            <child link="small_link_1_10"/>
            <axis xyz="1 0 0" />
        </joint>
        <joint name="joint_2_10" type="continuous">
            <parent link="small_link_1_10"/>
            <child link="small_link_2_10"/>
            <axis xyz="0 1 0" />
        </joint>
        <joint name="joint_1_10_" type="continuous">
            <parent link="small_link_2_10"/>
            <child link="tether_fragment_10"/>
            <axis xyz="0 0 1" />
        </joint>
            
        <link name="tether_fragment_11">
            <visual>
                <origin rpy="0 0 0" xyz="0 0 0.05"/>
                <geometry>
                    <cylinder length="0.1" radius="0.001"/>
                </geometry>
                <!--material name="black"/-->
            </visual>
            <inertial>
                <mass value="0.0001"/>
                <inertia ixx="8.33583333333e-08" iyy="8.33583333333e-08" izz="5e-11" ixy="0.0" ixz="0.0" iyz="0.0"/>
            </inertial>
        </link>
            
                <!--link between two tether fragments-->
        <link name="small_link_1_11">
            <inertial>
                <mass value="1e-05"/>
                <inertia ixx="1e-05" iyy="1e-05" izz="1e-05" ixy="0.0" ixz="0.0" iyz="0.0"/>
            </inertial>
        </link>
        <link name="small_link_2_11">
            <inertial>
                <mass value="1e-05"/>
                <inertia ixx="1e-05" iyy="1e-05" izz="1e-05" ixy="0.0" ixz="0.0" iyz="0.0"/>
            </inertial>
        </link>

        <!--tether fragment joint-->
        <joint name="joint_1_11" type="continuous">
            <origin rpy="0 0 0" xyz="0 0 0.1"/>
            <parent link="tether_fragment_10"/>
            <child link="small_link_1_11"/>
            <axis xyz="1 0 0" />
        </joint>
        <joint name="joint_2_11" type="continuous">
            <parent link="small_link_1_11"/>
            <child link="small_link_2_11"/>
            <axis xyz="0 1 0" />
        </joint>
        <joint name="joint_1_11_" type="continuous">
            <parent link="small_link_2_11"/>
            <child link="tether_fragment_11"/>
            <axis xyz="0 0 1" />
        </joint>
            
        <link name="tether_fragment_12">
            <visual>
                <origin rpy="0 0 0" xyz="0 0 0.05"/>
                <geometry>
                    <cylinder length="0.1" radius="0.001"/>
                </geometry>
                <!--material name="black"/-->
            </visual>
            <inertial>
                <mass value="0.0001"/>
                <inertia ixx="8.33583333333e-08" iyy="8.33583333333e-08" izz="5e-11" ixy="0.0" ixz="0.0" iyz="0.0"/>
            </inertial>
        </link>
            
                <!--link between two tether fragments-->
        <link name="small_link_1_12">
            <inertial>
                <mass value="1e-05"/>
                <inertia ixx="1e-05" iyy="1e-05" izz="1e-05" ixy="0.0" ixz="0.0" iyz="0.0"/>
            </inertial>
        </link>
        <link name="small_link_2_12">
            <inertial>
                <mass value="1e-05"/>
                <inertia ixx="1e-05" iyy="1e-05" izz="1e-05" ixy="0.0" ixz="0.0" iyz="0.0"/>
            </inertial>
        </link>

        <!--tether fragment joint-->
        <joint name="joint_1_12" type="continuous">
            <origin rpy="0 0 0" xyz="0 0 0.1"/>
            <parent link="tether_fragment_11"/>
            <child link="small_link_1_12"/>
            <axis xyz="1 0 0" />
        </joint>
        <joint name="joint_2_12" type="continuous">
            <parent link="small_link_1_12"/>
            <child link="small_link_2_12"/>
            <axis xyz="0 1 0" />
        </joint>
        <joint name="joint_1_12_" type="continuous">
            <parent link="small_link_2_12"/>
            <child link="tether_fragment_12"/>
            <axis xyz="0 0 1" />
        </joint>
            
        <link name="tether_fragment_13">
            <visual>
                <origin rpy="0 0 0" xyz="0 0 0.05"/>
                <geometry>
                    <cylinder length="0.1" radius="0.001"/>
                </geometry>
                <!--material name="black"/-->
            </visual>
            <inertial>
                <mass value="0.0001"/>
                <inertia ixx="8.33583333333e-08" iyy="8.33583333333e-08" izz="5e-11" ixy="0.0" ixz="0.0" iyz="0.0"/>
            </inertial>
        </link>
            
                <!--link between two tether fragments-->
        <link name="small_link_1_13">
            <inertial>
                <mass value="1e-05"/>
                <inertia ixx="1e-05" iyy="1e-05" izz="1e-05" ixy="0.0" ixz="0.0" iyz="0.0"/>
            </inertial>
        </link>
        <link name="small_link_2_13">
            <inertial>
                <mass value="1e-05"/>
                <inertia ixx="1e-05" iyy="1e-05" izz="1e-05" ixy="0.0" ixz="0.0" iyz="0.0"/>
            </inertial>
        </link>

        <!--tether fragment joint-->
        <joint name="joint_1_13" type="continuous">
            <origin rpy="0 0 0" xyz="0 0 0.1"/>
            <parent link="tether_fragment_12"/>
            <child link="small_link_1_13"/>
            <axis xyz="1 0 0" />
        </joint>
        <joint name="joint_2_13" type="continuous">
            <parent link="small_link_1_13"/>
            <child link="small_link_2_13"/>
            <axis xyz="0 1 0" />
        </joint>
        <joint name="joint_1_13_" type="continuous">
            <parent link="small_link_2_13"/>
            <child link="tether_fragment_13"/>
            <axis xyz="0 0 1" />
        </joint>
            
        <link name="tether_fragment_14">
            <visual>
                <origin rpy="0 0 0" xyz="0 0 0.05"/>
                <geometry>
                    <cylinder length="0.1" radius="0.001"/>
                </geometry>
                <!--material name="black"/-->
            </visual>
            <inertial>
                <mass value="0.0001"/>
                <inertia ixx="8.33583333333e-08" iyy="8.33583333333e-08" izz="5e-11" ixy="0.0" ixz="0.0" iyz="0.0"/>
            </inertial>
        </link>
            
                <!--link between two tether fragments-->
        <link name="small_link_1_14">
            <inertial>
                <mass value="1e-05"/>
                <inertia ixx="1e-05" iyy="1e-05" izz="1e-05" ixy="0.0" ixz="0.0" iyz="0.0"/>
            </inertial>
        </link>
        <link name="small_link_2_14">
            <inertial>
                <mass value="1e-05"/>
                <inertia ixx="1e-05" iyy="1e-05" izz="1e-05" ixy="0.0" ixz="0.0" iyz="0.0"/>
            </inertial>
        </link>

        <!--tether fragment joint-->
        <joint name="joint_1_14" type="continuous">
            <origin rpy="0 0 0" xyz="0 0 0.1"/>
            <parent link="tether_fragment_13"/>
            <child link="small_link_1_14"/>
            <axis xyz="1 0 0" />
        </joint>
        <joint name="joint_2_14" type="continuous">
            <parent link="small_link_1_14"/>
            <child link="small_link_2_14"/>
            <axis xyz="0 1 0" />
        </joint>
        <joint name="joint_1_14_" type="continuous">
            <parent link="small_link_2_14"/>
            <child link="tether_fragment_14"/>
            <axis xyz="0 0 1" />
        </joint>
            
        <link name="tether_fragment_15">
            <visual>
                <origin rpy="0 0 0" xyz="0 0 0.05"/>
                <geometry>
                    <cylinder length="0.1" radius="0.001"/>
                </geometry>
                <!--material name="black"/-->
            </visual>
            <inertial>
                <mass value="0.0001"/>
                <inertia ixx="8.33583333333e-08" iyy="8.33583333333e-08" izz="5e-11" ixy="0.0" ixz="0.0" iyz="0.0"/>
            </inertial>
        </link>
            
                <!--link between two tether fragments-->
        <link name="small_link_1_15">
            <inertial>
                <mass value="1e-05"/>
                <inertia ixx="1e-05" iyy="1e-05" izz="1e-05" ixy="0.0" ixz="0.0" iyz="0.0"/>
            </inertial>
        </link>
        <link name="small_link_2_15">
            <inertial>
                <mass value="1e-05"/>
                <inertia ixx="1e-05" iyy="1e-05" izz="1e-05" ixy="0.0" ixz="0.0" iyz="0.0"/>
            </inertial>
        </link>

        <!--tether fragment joint-->
        <joint name="joint_1_15" type="continuous">
            <origin rpy="0 0 0" xyz="0 0 0.1"/>
            <parent link="tether_fragment_14"/>
            <child link="small_link_1_15"/>
            <axis xyz="1 0 0" />
        </joint>
        <joint name="joint_2_15" type="continuous">
            <parent link="small_link_1_15"/>
            <child link="small_link_2_15"/>
            <axis xyz="0 1 0" />
        </joint>
        <joint name="joint_1_15_" type="continuous">
            <parent link="small_link_2_15"/>
            <child link="tether_fragment_15"/>
            <axis xyz="0 0 1" />
        </joint>
            
        <link name="tether_fragment_16">
            <visual>
                <origin rpy="0 0 0" xyz="0 0 0.05"/>
                <geometry>
                    <cylinder length="0.1" radius="0.001"/>
                </geometry>
                <!--material name="black"/-->
            </visual>
            <inertial>
                <mass value="0.0001"/>
                <inertia ixx="8.33583333333e-08" iyy="8.33583333333e-08" izz="5e-11" ixy="0.0" ixz="0.0" iyz="0.0"/>
            </inertial>
        </link>
            
                <!--link between two tether fragments-->
        <link name="small_link_1_16">
            <inertial>
                <mass value="1e-05"/>
                <inertia ixx="1e-05" iyy="1e-05" izz="1e-05" ixy="0.0" ixz="0.0" iyz="0.0"/>
            </inertial>
        </link>
        <link name="small_link_2_16">
            <inertial>
                <mass value="1e-05"/>
                <inertia ixx="1e-05" iyy="1e-05" izz="1e-05" ixy="0.0" ixz="0.0" iyz="0.0"/>
            </inertial>
        </link>

        <!--tether fragment joint-->
        <joint name="joint_1_16" type="continuous">
            <origin rpy="0 0 0" xyz="0 0 0.1"/>
            <parent link="tether_fragment_15"/>
            <child link="small_link_1_16"/>
            <axis xyz="1 0 0" />
        </joint>
        <joint name="joint_2_16" type="continuous">
            <parent link="small_link_1_16"/>
            <child link="small_link_2_16"/>
            <axis xyz="0 1 0" />
        </joint>
        <joint name="joint_1_16_" type="continuous">
            <parent link="small_link_2_16"/>
            <child link="tether_fragment_16"/>
            <axis xyz="0 0 1" />
        </joint>
            
        <link name="tether_fragment_17">
            <visual>
                <origin rpy="0 0 0" xyz="0 0 0.05"/>
                <geometry>
                    <cylinder length="0.1" radius="0.001"/>
                </geometry>
                <!--material name="black"/-->
            </visual>
            <inertial>
                <mass value="0.0001"/>
                <inertia ixx="8.33583333333e-08" iyy="8.33583333333e-08" izz="5e-11" ixy="0.0" ixz="0.0" iyz="0.0"/>
            </inertial>
        </link>
            
                <!--link between two tether fragments-->
        <link name="small_link_1_17">
            <inertial>
                <mass value="1e-05"/>
                <inertia ixx="1e-05" iyy="1e-05" izz="1e-05" ixy="0.0" ixz="0.0" iyz="0.0"/>
            </inertial>
        </link>
        <link name="small_link_2_17">
            <inertial>
                <mass value="1e-05"/>
                <inertia ixx="1e-05" iyy="1e-05" izz="1e-05" ixy="0.0" ixz="0.0" iyz="0.0"/>
            </inertial>
        </link>

        <!--tether fragment joint-->
        <joint name="joint_1_17" type="continuous">
            <origin rpy="0 0 0" xyz="0 0 0.1"/>
            <parent link="tether_fragment_16"/>
            <child link="small_link_1_17"/>
            <axis xyz="1 0 0" />
        </joint>
        <joint name="joint_2_17" type="continuous">
            <parent link="small_link_1_17"/>
            <child link="small_link_2_17"/>
            <axis xyz="0 1 0" />
        </joint>
        <joint name="joint_1_17_" type="continuous">
            <parent link="small_link_2_17"/>
            <child link="tether_fragment_17"/>
            <axis xyz="0 0 1" />
        </joint>
            
        <link name="tether_fragment_18">
            <visual>
                <origin rpy="0 0 0" xyz="0 0 0.05"/>
                <geometry>
                    <cylinder length="0.1" radius="0.001"/>
                </geometry>
                <!--material name="black"/-->
            </visual>
            <inertial>
                <mass value="0.0001"/>
                <inertia ixx="8.33583333333e-08" iyy="8.33583333333e-08" izz="5e-11" ixy="0.0" ixz="0.0" iyz="0.0"/>
            </inertial>
        </link>
            
                <!--link between two tether fragments-->
        <link name="small_link_1_18">
            <inertial>
                <mass value="1e-05"/>
                <inertia ixx="1e-05" iyy="1e-05" izz="1e-05" ixy="0.0" ixz="0.0" iyz="0.0"/>
            </inertial>
        </link>
        <link name="small_link_2_18">
            <inertial>
                <mass value="1e-05"/>
                <inertia ixx="1e-05" iyy="1e-05" izz="1e-05" ixy="0.0" ixz="0.0" iyz="0.0"/>
            </inertial>
        </link>

        <!--tether fragment joint-->
        <joint name="joint_1_18" type="continuous">
            <origin rpy="0 0 0" xyz="0 0 0.1"/>
            <parent link="tether_fragment_17"/>
            <child link="small_link_1_18"/>
            <axis xyz="1 0 0" />
        </joint>
        <joint name="joint_2_18" type="continuous">
            <parent link="small_link_1_18"/>
            <child link="small_link_2_18"/>
            <axis xyz="0 1 0" />
        </joint>
        <joint name="joint_1_18_" type="continuous">
            <parent link="small_link_2_18"/>
            <child link="tether_fragment_18"/>
            <axis xyz="0 0 1" />
        </joint>
            
        <link name="tether_fragment_19">
            <visual>
                <origin rpy="0 0 0" xyz="0 0 0.05"/>
                <geometry>
                    <cylinder length="0.1" radius="0.001"/>
                </geometry>
                <!--material name="black"/-->
            </visual>
            <inertial>
                <mass value="0.0001"/>
                <inertia ixx="8.33583333333e-08" iyy="8.33583333333e-08" izz="5e-11" ixy="0.0" ixz="0.0" iyz="0.0"/>
            </inertial>
        </link>
            
                <!--link between two tether fragments-->
        <link name="small_link_1_19">
            <inertial>
                <mass value="1e-05"/>
                <inertia ixx="1e-05" iyy="1e-05" izz="1e-05" ixy="0.0" ixz="0.0" iyz="0.0"/>
            </inertial>
        </link>
        <link name="small_link_2_19">
            <inertial>
                <mass value="1e-05"/>
                <inertia ixx="1e-05" iyy="1e-05" izz="1e-05" ixy="0.0" ixz="0.0" iyz="0.0"/>
            </inertial>
        </link>

        <!--tether fragment joint-->
        <joint name="joint_1_19" type="continuous">
            <origin rpy="0 0 0" xyz="0 0 0.1"/>
            <parent link="tether_fragment_18"/>
            <child link="small_link_1_19"/>
            <axis xyz="1 0 0" />
        </joint>
        <joint name="joint_2_19" type="continuous">
            <parent link="small_link_1_19"/>
            <child link="small_link_2_19"/>
            <axis xyz="0 1 0" />
        </joint>
        <joint name="joint_1_19_" type="continuous">
            <parent link="small_link_2_19"/>
            <child link="tether_fragment_19"/>
            <axis xyz="0 0 1" />
        </joint>
            
        <gazebo>
            <plugin name="gazebo_ros_control" filename="libgazebo_ros_control.so">
                <robotNamespace>tether</robotNamespace>
            </plugin>
        </gazebo>

    </xacro:macro>
</robot>